Workbook

Sheet Inp_CER_Bin_2eps3arms
A1: ModelID | B1: Scenario | C1: Method | D1: SampleSize | E1: alpha | F1: TestStatCont | G1: CommonStdDev | H1: TestStatBin | I1: FWERControl | J1: nArms | K1: nEps | L1: lEpType | M1: Arms.Mean | N1: Arms.std.dev | O1: Arms.Prop | P1: Arms.alloc.ratio | Q1: EP.Corr | R1: WI | S1: G | T1: test.type | U1: info_frac | V1: typeOfDesign | W1: MultipleWinners | X1: Selection | Y1: SelectionLook | Z1: SelectEndPoint | AA1: SelectionScale | AB1: SelectionCriterion | AC1: SelectionParmeter | AD1: KeepAssosiatedEps | AE1: ImplicitSSR | AF1: nSimulation | AG1: nSimulation_Stage2 | AH1: Seed | AI1: SummaryStat | AJ1: plotGraphs | AK1: Parallel | AL1: UseCC | AM1: Matching.Pair | AN1: Test.Suite | AO1: Compare.Set
A2: 1 | B2: No selection, Partly-Parametric | C2: CER | D2: 600 | E2: 0.025 | F2: NA | G2: NA | H2: UnPooled | I2: CombinationTest | J2: 3 | K2: 2 | L2: list('EP1' = 'Binary', 'EP2' = 'Binary') | M2: NA | N2: NA | O2: list('EP1' = c(0.4, 0.4, 0.4), 'EP2' = c(0.5, 0.5, 0.5)) | P2: c(1,1,1) | Q2: matrix(c(1, 0.5, 0.5, 1), nrow = nEps) | R2: c(rep(1/4, 4)) | S2: rbind(H1=c(0, 1/3, 1/3, 1/3), H2=c(1/3, 0, 1/3, 1/3), H3=c(1/3, 1/3, 0, 1/3), H4=c(1/3, 1/3, 1/3, 0)) | T2: Partly-Parametric | U2: c(0.5, 1) | V2: asOF | W2: FALSE | X2: FALSE | Y2: NA | Z2: NA | AA2: NA | AB2: NA | AC2: NA | AD2: NA | AE2: None | AF2: 20000 | AG2: 2000 | AH2: 1234 | AI2: TRUE | AJ2: FALSE | AK2: TRUE | AL2: TRUE
A3: 2 | B3: No selection, Partly-Parametric | C3: CER | D3: 1500 | E3: 0.025 | F3: NA | G3: NA | H3: UnPooled | I3: CombinationTest | J3: 3 | K3: 2 | L3: list('EP1' = 'Binary', 'EP2' = 'Binary') | M3: NA | N3: NA | O3: list('EP1' = c(0.4, 0.4, 0.4), 'EP2' = c(0.5, 0.5, 0.5)) | P3: c(1,1,1) | Q3: matrix(c(1, 0.5, 0.5, 1), nrow = nEps) | R3: c(rep(1/4, 4)) | S3: rbind(H1=c(0, 1/3, 1/3, 1/3), H2=c(1/3, 0, 1/3, 1/3), H3=c(1/3, 1/3, 0, 1/3), H4=c(1/3, 1/3, 1/3, 0)) | T3: Partly-Parametric | U3: c(0.5, 1) | V3: asOF | W3: FALSE | X3: FALSE | Y3: NA | Z3: NA | AA3: NA | AB3: NA | AC3: NA | AD3: NA | AE3: None | AF3: 20000 | AG3: 2000 | AH3: 1234 | AI3: TRUE | AJ3: FALSE | AK3: TRUE | AL3: TRUE
A4: 3 | B4: No selection, Partly-Parametric | C4: CER | D4: 3000 | E4: 0.025 | F4: NA | G4: NA | H4: UnPooled | I4: CombinationTest | J4: 3 | K4: 2 | L4: list('EP1' = 'Binary', 'EP2' = 'Binary') | M4: NA | N4: NA | O4: list('EP1' = c(0.4, 0.4, 0.4), 'EP2' = c(0.5, 0.5, 0.5)) | P4: c(1,1,1) | Q4: matrix(c(1, 0.5, 0.5, 1), nrow = nEps) | R4: c(rep(1/4, 4)) | S4: rbind(H1=c(0, 1/3, 1/3, 1/3), H2=c(1/3, 0, 1/3, 1/3), H3=c(1/3, 1/3, 0, 1/3), H4=c(1/3, 1/3, 1/3, 0)) | T4: Partly-Parametric | U4: c(0.5, 1) | V4: asOF | W4: FALSE | X4: FALSE | Y4: NA | Z4: NA | AA4: NA | AB4: NA | AC4: NA | AD4: NA | AE4: None | AF4: 20000 | AG4: 2000 | AH4: 1234 | AI4: TRUE | AJ4: FALSE | AK4: TRUE | AL4: TRUE
A5: 4 | B5: No selection, Partly-Parametric | C5: CER | D5: 5000 | E5: 0.025 | F5: NA | G5: NA | H5: UnPooled | I5: CombinationTest | J5: 3 | K5: 2 | L5: list('EP1' = 'Binary', 'EP2' = 'Binary') | M5: NA | N5: NA | O5: list('EP1' = c(0.4, 0.4, 0.4), 'EP2' = c(0.5, 0.5, 0.5)) | P5: c(1,1,1) | Q5: matrix(c(1, 0.5, 0.5, 1), nrow = nEps) | R5: c(rep(1/4, 4)) | S5: rbind(H1=c(0, 1/3, 1/3, 1/3), H2=c(1/3, 0, 1/3, 1/3), H3=c(1/3, 1/3, 0, 1/3), H4=c(1/3, 1/3, 1/3, 0)) | T5: Partly-Parametric | U5: c(0.5, 1) | V5: asOF | W5: FALSE | X5: FALSE | Y5: NA | Z5: NA | AA5: NA | AB5: NA | AC5: NA | AD5: NA | AE5: None | AF5: 20000 | AG5: 2000 | AH5: 1234 | AI5: TRUE | AJ5: FALSE | AK5: TRUE | AL5: TRUE
A6: 5 | B6: Fut=0.25,N=600,MultWin=F | C6: CER | D6: 600 | E6: 0.025 | F6: NA | G6: NA | H6: UnPooled | I6: CombinationTest | J6: 3 | K6: 2 | L6: list('EP1' = 'Binary', 'EP2' = 'Binary') | M6: NA | N6: NA | O6: list('EP1' = c(0.4, 0.4, 0.4), 'EP2' = c(0.5, 0.5, 0.5)) | P6: c(1,1,1) | Q6: matrix(c(1, 0.5, 0.5, 1), nrow = nEps) | R6: c(rep(1/4, 4)) | S6: rbind(H1=c(0, 1/3, 1/3, 1/3), H2=c(1/3, 0, 1/3, 1/3), H3=c(1/3, 1/3, 0, 1/3), H4=c(1/3, 1/3, 1/3, 0)) | T6: Partly-Parametric | U6: c(0.5, 1) | V6: asOF | W6: FALSE | X6: TRUE | Y6: 1 | Z6: 1 | AA6: pvalue | AB6: threshold | AC6: 0.25 | AD6: TRUE | AE6: Selection | AF6: 20000 | AG6: 2000 | AH6: 745664 | AI6: TRUE | AJ6: FALSE | AK6: TRUE | AL6: TRUE
A7: 6 | B7: Fut=0.25,N=2000,MultWin=F | C7: CER | D7: 2000 | E7: 0.025 | F7: NA | G7: NA | H7: UnPooled | I7: CombinationTest | J7: 3 | K7: 2 | L7: list('EP1' = 'Binary', 'EP2' = 'Binary') | M7: NA | N7: NA | O7: list('EP1' = c(0.4, 0.4, 0.4), 'EP2' = c(0.5, 0.5, 0.5)) | P7: c(1,1,1) | Q7: matrix(c(1, 0.5, 0.5, 1), nrow = nEps) | R7: c(rep(1/4, 4)) | S7: rbind(H1=c(0, 1/3, 1/3, 1/3), H2=c(1/3, 0, 1/3, 1/3), H3=c(1/3, 1/3, 0, 1/3), H4=c(1/3, 1/3, 1/3, 0)) | T7: Partly-Parametric | U7: c(0.5, 1) | V7: asOF | W7: FALSE | X7: TRUE | Y7: 1 | Z7: 1 | AA7: pvalue | AB7: threshold | AC7: 0.25 | AD7: TRUE | AE7: Selection | AF7: 20000 | AG7: 2000 | AH7: 745664 | AI7: TRUE | AJ7: FALSE | AK7: TRUE | AL7: TRUE
A8: 7 | B8: Best=1,N=600,MultWin=F | C8: CER | D8: 600 | E8: 0.025 | F8: NA | G8: NA | H8: UnPooled | I8: CombinationTest | J8: 3 | K8: 2 | L8: list('EP1' = 'Binary', 'EP2' = 'Binary') | M8: NA | N8: NA | O8: list('EP1' = c(0.4, 0.4, 0.4), 'EP2' = c(0.5, 0.5, 0.5)) | P8: c(1,1,1) | Q8: matrix(c(1, 0.5, 0.5, 1), nrow = nEps) | R8: c(rep(1/4, 4)) | S8: rbind(H1=c(0, 1/3, 1/3, 1/3), H2=c(1/3, 0, 1/3, 1/3), H3=c(1/3, 1/3, 0, 1/3), H4=c(1/3, 1/3, 1/3, 0)) | T8: Partly-Parametric | U8: c(0.5, 1) | V8: asOF | W8: FALSE | X8: TRUE | Y8: 1 | Z8: 1 | AA8: pvalue | AB8: best | AC8: 1 | AD8: TRUE | AE8: Selection | AF8: 20000 | AG8: 2000 | AH8: 745664 | AI8: TRUE | AJ8: FALSE | AK8: TRUE | AL8: TRUE
A9: 8 | B9: Best=1,N=2000,MultWin=F | C9: CER | D9: 2000 | E9: 0.025 | F9: NA | G9: NA | H9: UnPooled | I9: CombinationTest | J9: 3 | K9: 2 | L9: list('EP1' = 'Binary', 'EP2' = 'Binary') | M9: NA | N9: NA | O9: list('EP1' = c(0.4, 0.4, 0.4), 'EP2' = c(0.5, 0.5, 0.5)) | P9: c(1,1,1) | Q9: matrix(c(1, 0.5, 0.5, 1), nrow = nEps) | R9: c(rep(1/4, 4)) | S9: rbind(H1=c(0, 1/3, 1/3, 1/3), H2=c(1/3, 0, 1/3, 1/3), H3=c(1/3, 1/3, 0, 1/3), H4=c(1/3, 1/3, 1/3, 0)) | T9: Partly-Parametric | U9: c(0.5, 1) | V9: asOF | W9: FALSE | X9: TRUE | Y9: 1 | Z9: 1 | AA9: pvalue | AB9: best | AC9: 1 | AD9: TRUE | AE9: Selection | AF9: 20000 | AG9: 2000 | AH9: 745664 | AI9: TRUE | AJ9: FALSE | AK9: TRUE | AL9: TRUE
A10: 9 | B10: No selection,N=2000,MultWin=T | C10: CER | D10: 2000 | E10: 0.025 | F10: NA | G10: NA | H10: UnPooled | I10: CombinationTest | J10: 3 | K10: 2 | L10: list('EP1' = 'Binary', 'EP2' = 'Binary') | M10: NA | N10: NA | O10: list('EP1' = c(0.4, 0.4, 0.4), 'EP2' = c(0.5, 0.5, 0.5)) | P10: c(1,1,1) | Q10: matrix(c(1, 0.5, 0.5, 1), nrow = nEps) | R10: c(rep(1/4, 4)) | S10: rbind(H1=c(0, 1/3, 1/3, 1/3), H2=c(1/3, 0, 1/3, 1/3), H3=c(1/3, 1/3, 0, 1/3), H4=c(1/3, 1/3, 1/3, 0)) | T10: Partly-Parametric | U10: c(0.5, 1) | V10: asOF | W10: TRUE | X10: FALSE | Y10: NA | Z10: NA | AA10: NA | AB10: NA | AC10: NA | AD10: NA | AE10: None | AF10: 20000 | AG10: 2000 | AH10: 6534 | AI10: TRUE | AJ10: FALSE | AK10: TRUE | AL10: TRUE
A11: 10 | B11: Fut=0.25,N=2000,MultWin=T | C11: CER | D11: 2000 | E11: 0.025 | F11: NA | G11: NA | H11: UnPooled | I11: CombinationTest | J11: 3 | K11: 2 | L11: list('EP1' = 'Binary', 'EP2' = 'Binary') | M11: NA | N11: NA | O11: list('EP1' = c(0.4, 0.4, 0.4), 'EP2' = c(0.5, 0.5, 0.5)) | P11: c(1,1,1) | Q11: matrix(c(1, 0.5, 0.5, 1), nrow = nEps) | R11: c(rep(1/4, 4)) | S11: rbind(H1=c(0, 1/3, 1/3, 1/3), H2=c(1/3, 0, 1/3, 1/3), H3=c(1/3, 1/3, 0, 1/3), H4=c(1/3, 1/3, 1/3, 0)) | T11: Partly-Parametric | U11: c(0.5, 1) | V11: asOF | W11: TRUE | X11: TRUE | Y11: 1 | Z11: 1 | AA11: pvalue | AB11: threshold | AC11: 0.25 | AD11: TRUE | AE11: Selection | AF11: 20000 | AG11: 2000 | AH11: 6534 | AI11: TRUE | AJ11: FALSE | AK11: TRUE | AL11: TRUE
A12: 11 | B12: Best=1,N=2000,MultWin=T | C12: CER | D12: 2000 | E12: 0.025 | F12: NA | G12: NA | H12: UnPooled | I12: CombinationTest | J12: 3 | K12: 2 | L12: list('EP1' = 'Binary', 'EP2' = 'Binary') | M12: NA | N12: NA | O12: list('EP1' = c(0.4, 0.4, 0.4), 'EP2' = c(0.5, 0.5, 0.5)) | P12: c(1,1,1) | Q12: matrix(c(1, 0.5, 0.5, 1), nrow = nEps) | R12: c(rep(1/4, 4)) | S12: rbind(H1=c(0, 1/3, 1/3, 1/3), H2=c(1/3, 0, 1/3, 1/3), H3=c(1/3, 1/3, 0, 1/3), H4=c(1/3, 1/3, 1/3, 0)) | T12: Partly-Parametric | U12: c(0.5, 1) | V12: asOF | W12: TRUE | X12: TRUE | Y12: 1 | Z12: 1 | AA12: pvalue | AB12: best | AC12: 1 | AD12: TRUE | AE12: Selection | AF12: 20000 | AG12: 2000 | AH12: 6534 | AI12: TRUE | AJ12: FALSE | AK12: TRUE | AL12: TRUE
A13: 12 | B13: No selection,N=2000,Pooled | C13: CER | D13: 2000 | E13: 0.025 | F13: NA | G13: NA | H13: Pooled | I13: CombinationTest | J13: 3 | K13: 2 | L13: list('EP1' = 'Binary', 'EP2' = 'Binary') | M13: NA | N13: NA | O13: list('EP1' = c(0.4, 0.4, 0.4), 'EP2' = c(0.5, 0.5, 0.5)) | P13: c(1,1,1) | Q13: matrix(c(1, 0.5, 0.5, 1), nrow = nEps) | R13: c(rep(1/4, 4)) | S13: rbind(H1=c(0, 1/3, 1/3, 1/3), H2=c(1/3, 0, 1/3, 1/3), H3=c(1/3, 1/3, 0, 1/3), H4=c(1/3, 1/3, 1/3, 0)) | T13: Partly-Parametric | U13: c(0.5, 1) | V13: asOF | W13: FALSE | X13: FALSE | Y13: NA | Z13: NA | AA13: NA | AB13: NA | AC13: NA | AD13: NA | AE13: None | AF13: 20000 | AG13: 2000 | AH13: 6534 | AI13: TRUE | AJ13: FALSE | AK13: TRUE | AL13: TRUE
A14: 13 | B14: Fut=0.25,N=2000,Pooled | C14: CER | D14: 2000 | E14: 0.025 | F14: NA | G14: NA | H14: Pooled | I14: CombinationTest | J14: 3 | K14: 2 | L14: list('EP1' = 'Binary', 'EP2' = 'Binary') | M14: NA | N14: NA | O14: list('EP1' = c(0.4, 0.4, 0.4), 'EP2' = c(0.5, 0.5, 0.5)) | P14: c(1,1,1) | Q14: matrix(c(1, 0.5, 0.5, 1), nrow = nEps) | R14: c(rep(1/4, 4)) | S14: rbind(H1=c(0, 1/3, 1/3, 1/3), H2=c(1/3, 0, 1/3, 1/3), H3=c(1/3, 1/3, 0, 1/3), H4=c(1/3, 1/3, 1/3, 0)) | T14: Partly-Parametric | U14: c(0.5, 1) | V14: asOF | W14: FALSE | X14: TRUE | Y14: 1 | Z14: 1 | AA14: pvalue | AB14: threshold | AC14: 0.25 | AD14: TRUE | AE14: Selection | AF14: 20000 | AG14: 2000 | AH14: 6534 | AI14: TRUE | AJ14: FALSE | AK14: TRUE | AL14: TRUE
A15: 14 | B15: Best=1,N=2000,Pooled | C15: CER | D15: 2000 | E15: 0.025 | F15: NA | G15: NA | H15: Pooled | I15: CombinationTest | J15: 3 | K15: 2 | L15: list('EP1' = 'Binary', 'EP2' = 'Binary') | M15: NA | N15: NA | O15: list('EP1' = c(0.4, 0.4, 0.4), 'EP2' = c(0.5, 0.5, 0.5)) | P15: c(1,1,1) | Q15: matrix(c(1, 0.5, 0.5, 1), nrow = nEps) | R15: c(rep(1/4, 4)) | S15: rbind(H1=c(0, 1/3, 1/3, 1/3), H2=c(1/3, 0, 1/3, 1/3), H3=c(1/3, 1/3, 0, 1/3), H4=c(1/3, 1/3, 1/3, 0)) | T15: Partly-Parametric | U15: c(0.5, 1) | V15: asOF | W15: FALSE | X15: TRUE | Y15: 1 | Z15: 1 | AA15: pvalue | AB15: best | AC15: 1 | AD15: TRUE | AE15: Selection | AF15: 20000 | AG15: 2000 | AH15: 6534 | AI15: TRUE | AJ15: FALSE | AK15: TRUE | AL15: TRUE
A16: 15 | B16: No selection,N=2000,CumStat | C16: CER | D16: 2000 | E16: 0.025 | F16: NA | G16: NA | H16: UnPooled | I16: None | J16: 3 | K16: 2 | L16: list('EP1' = 'Binary', 'EP2' = 'Binary') | M16: NA | N16: NA | O16: list('EP1' = c(0.4, 0.4, 0.4), 'EP2' = c(0.5, 0.5, 0.5)) | P16: c(1,1,1) | Q16: matrix(c(1, 0.5, 0.5, 1), nrow = nEps) | R16: c(rep(1/4, 4)) | S16: rbind(H1=c(0, 1/3, 1/3, 1/3), H2=c(1/3, 0, 1/3, 1/3), H3=c(1/3, 1/3, 0, 1/3), H4=c(1/3, 1/3, 1/3, 0)) | T16: Partly-Parametric | U16: c(0.5, 1) | V16: asOF | W16: FALSE | X16: FALSE | Y16: NA | Z16: NA | AA16: NA | AB16: NA | AC16: NA | AD16: NA | AE16: None | AF16: 20000 | AG16: 2000 | AH16: 6534 | AI16: TRUE | AJ16: FALSE | AK16: TRUE | AL16: TRUE
A17: 16 | B17: Fut=0.25,N=2000,CumStat | C17: CER | D17: 2000 | E17: 0.025 | F17: NA | G17: NA | H17: UnPooled | I17: None | J17: 3 | K17: 2 | L17: list('EP1' = 'Binary', 'EP2' = 'Binary') | M17: NA | N17: NA | O17: list('EP1' = c(0.4, 0.4, 0.4), 'EP2' = c(0.5, 0.5, 0.5)) | P17: c(1,1,1) | Q17: matrix(c(1, 0.5, 0.5, 1), nrow = nEps) | R17: c(rep(1/4, 4)) | S17: rbind(H1=c(0, 1/3, 1/3, 1/3), H2=c(1/3, 0, 1/3, 1/3), H3=c(1/3, 1/3, 0, 1/3), H4=c(1/3, 1/3, 1/3, 0)) | T17: Partly-Parametric | U17: c(0.5, 1) | V17: asOF | W17: FALSE | X17: TRUE | Y17: 1 | Z17: 1 | AA17: pvalue | AB17: threshold | AC17: 0.25 | AD17: TRUE | AE17: Selection | AF17: 20000 | AG17: 2000 | AH17: 6534 | AI17: TRUE | AJ17: FALSE | AK17: TRUE | AL17: TRUE
A18: 17 | B18: Best=1,N=2000,CumStat | C18: CER | D18: 2000 | E18: 0.025 | F18: NA | G18: NA | H18: UnPooled | I18: None | J18: 3 | K18: 2 | L18: list('EP1' = 'Binary', 'EP2' = 'Binary') | M18: NA | N18: NA | O18: list('EP1' = c(0.4, 0.4, 0.4), 'EP2' = c(0.5, 0.5, 0.5)) | P18: c(1,1,1) | Q18: matrix(c(1, 0.5, 0.5, 1), nrow = nEps) | R18: c(rep(1/4, 4)) | S18: rbind(H1=c(0, 1/3, 1/3, 1/3), H2=c(1/3, 0, 1/3, 1/3), H3=c(1/3, 1/3, 0, 1/3), H4=c(1/3, 1/3, 1/3, 0)) | T18: Partly-Parametric | U18: c(0.5, 1) | V18: asOF | W18: FALSE | X18: TRUE | Y18: 1 | Z18: 1 | AA18: pvalue | AB18: best | AC18: 1 | AD18: TRUE | AE18: Selection | AF18: 20000 | AG18: 2000 | AH18: 6534 | AI18: TRUE | AJ18: FALSE | AK18: TRUE | AL18: TRUE
A19: 18 | B19: S0, No Select, No CC, CPV | C19: CombPValue | D19: 2000 | E19: 0.025 | F19: NA | G19: NA | H19: UnPooled | I19: CombinationTest | J19: 5 | K19: 2 | L19: list(EP1 = "Binary", EP2 = "Binary") | M19: NA | N19: NA | O19: list(EP1 = c(0.22, 0.22, 0.22, 0.22, 0.22), EP2 = c(0.1, 0.1, 0.1, 0.1, 0.1)) | P19: c(1,1,1,1,1) | Q19: matrix(c(1, 0.5, 0.5, 1), byrow = T, nrow = 2) | R19: c(0.25,0.25,0.25,0.25, 0, 0, 0, 0) | S19: matrix(c(0,1/12,1/12,1/12,3/4,0,0,0, 1/12,0,1/12,1/12,0,3/4,0,0, 1/12,1/12,0,1/12,0,0,3/4,0, 1/12,1/12,1/12,0,0,0,0,3/4, 0,1/3,1/3,1/3,0,0,0,0, 1/3,0,1/3,1/3,0,0,0,0, 1/3,1/3,0,1/3,0,0,0,0, 1/3,1/3,1/3,0,0,0,0,0), nrow = nEps*(nArms-1), byrow = T) | T19: Partly-Parametric | U19: c(0.5, 1) | V19: asOF | W19: TRUE | X19: FALSE | Y19: NA | Z19: NA | AA19: NA | AB19: NA | AC19: NA | AD19: NA | AE19: None | AF19: 20000 | AG19: 500 | AH19: Random | AI19: FALSE | AJ19: FALSE | AK19: TRUE | AL19: FALSE
A20: 19 | B20: S0, No Select, No CC, CER | C20: CER | D20: 2000 | E20: 0.025 | F20: NA | G20: NA | H20: UnPooled | I20: CombinationTest | J20: 5 | K20: 2 | L20: list(EP1 = "Binary", EP2 = "Binary") | M20: NA | N20: NA | O20: list(EP1 = c(0.22, 0.22, 0.22, 0.22, 0.22), EP2 = c(0.1, 0.1, 0.1, 0.1, 0.1)) | P20: c(1,1,1,1,1) | Q20: matrix(c(1, 0.5, 0.5, 1), byrow = T, nrow = 2) | R20: c(0.25,0.25,0.25,0.25, 0, 0, 0, 0) | S20: matrix(c(0,1/12,1/12,1/12,3/4,0,0,0, 1/12,0,1/12,1/12,0,3/4,0,0, 1/12,1/12,0,1/12,0,0,3/4,0, 1/12,1/12,1/12,0,0,0,0,3/4, 0,1/3,1/3,1/3,0,0,0,0, 1/3,0,1/3,1/3,0,0,0,0, 1/3,1/3,0,1/3,0,0,0,0, 1/3,1/3,1/3,0,0,0,0,0), nrow = nEps*(nArms-1), byrow = T) | T20: Partly-Parametric | U20: c(0.5, 1) | V20: asOF | W20: TRUE | X20: FALSE | Y20: NA | Z20: NA | AA20: NA | AB20: NA | AC20: NA | AD20: NA | AE20: None | AF20: 20000 | AG20: 500 | AH20: Random | AI20: FALSE | AJ20: FALSE | AK20: TRUE | AL20: FALSE
A21: 20 | B21: S0, Conservative, No CC, CPV | C21: CombPValue | D21: 2000 | E21: 0.025 | F21: NA | G21: NA | H21: UnPooled | I21: CombinationTest | J21: 5 | K21: 2 | L21: list(EP1 = "Binary", EP2 = "Binary") | M21: NA | N21: NA | O21: list(EP1 = c(0.22, 0.22, 0.22, 0.22, 0.22), EP2 = c(0.1, 0.1, 0.1, 0.1, 0.1)) | P21: c(1,1,1,1,1) | Q21: matrix(c(1,0.5,0.5,1),nrow = 2) | R21: c(0.25,0.25,0.25,0.25, 0, 0, 0, 0) | S21: matrix(c(0,1/12,1/12,1/12,3/4,0,0,0, 1/12,0,1/12,1/12,0,3/4,0,0, 1/12,1/12,0,1/12,0,0,3/4,0, 1/12,1/12,1/12,0,0,0,0,3/4, 0,1/3,1/3,1/3,0,0,0,0, 1/3,0,1/3,1/3,0,0,0,0, 1/3,1/3,0,1/3,0,0,0,0, 1/3,1/3,1/3,0,0,0,0,0), nrow = nEps*(nArms-1), byrow = T) | T21: Partly-Parametric | U21: c(1/2,1) | V21: asOF | W21: TRUE | X21: TRUE | Y21: 1 | Z21: 1 | AA21: pvalue | AB21: threshold | AC21: 0.75 | AD21: TRUE | AE21: Selection | AF21: 20000 | AG21: 500 | AH21: Random | AI21: FALSE | AJ21: FALSE | AK21: TRUE | AL21: FALSE
A22: 21 | B22: S0, Conservative, No CC, CER | C22: CER | D22: 2000 | E22: 0.025 | F22: NA | G22: NA | H22: UnPooled | I22: CombinationTest | J22: 5 | K22: 2 | L22: list(EP1 = "Binary", EP2 = "Binary") | M22: NA | N22: NA | O22: list(EP1 = c(0.22, 0.22, 0.22, 0.22, 0.22), EP2 = c(0.1, 0.1, 0.1, 0.1, 0.1)) | P22: c(1,1,1,1,1) | Q22: matrix(c(1,0.5,0.5,1),nrow = 2) | R22: c(0.25,0.25,0.25,0.25, 0, 0, 0, 0) | S22: matrix(c(0,1/12,1/12,1/12,3/4,0,0,0, 1/12,0,1/12,1/12,0,3/4,0,0, 1/12,1/12,0,1/12,0,0,3/4,0, 1/12,1/12,1/12,0,0,0,0,3/4, 0,1/3,1/3,1/3,0,0,0,0, 1/3,0,1/3,1/3,0,0,0,0, 1/3,1/3,0,1/3,0,0,0,0, 1/3,1/3,1/3,0,0,0,0,0), nrow = nEps*(nArms-1), byrow = T) | T22: Partly-Parametric | U22: c(1/2,1) | V22: asOF | W22: TRUE | X22: TRUE | Y22: 1 | Z22: 1 | AA22: pvalue | AB22: threshold | AC22: 0.75 | AD22: TRUE | AE22: Selection | AF22: 20000 | AG22: 500 | AH22: Random | AI22: FALSE | AJ22: FALSE | AK22: TRUE | AL22: FALSE
A23: 22 | B23: S0, Normal, No CC, CPV | C23: CombPValue | D23: 2000 | E23: 0.025 | F23: NA | G23: NA | H23: UnPooled | I23: CombinationTest | J23: 5 | K23: 2 | L23: list(EP1 = "Binary", EP2 = "Binary") | M23: NA | N23: NA | O23: list(EP1 = c(0.22, 0.22, 0.22, 0.22, 0.22), EP2 = c(0.1, 0.1, 0.1, 0.1, 0.1)) | P23: c(1,1,1,1,1) | Q23: matrix(c(1,0.5,0.5,1),nrow = 2) | R23: c(0.25,0.25,0.25,0.25, 0, 0, 0, 0) | S23: matrix(c(0,1/12,1/12,1/12,3/4,0,0,0, 1/12,0,1/12,1/12,0,3/4,0,0, 1/12,1/12,0,1/12,0,0,3/4,0, 1/12,1/12,1/12,0,0,0,0,3/4, 0,1/3,1/3,1/3,0,0,0,0, 1/3,0,1/3,1/3,0,0,0,0, 1/3,1/3,0,1/3,0,0,0,0, 1/3,1/3,1/3,0,0,0,0,0), nrow = nEps*(nArms-1), byrow = T) | T23: Partly-Parametric | U23: c(1/2,1) | V23: asOF | W23: TRUE | X23: TRUE | Y23: 1 | Z23: 1 | AA23: pvalue | AB23: threshold | AC23: 0.5 | AD23: TRUE | AE23: Selection | AF23: 20000 | AG23: 500 | AH23: Random | AI23: FALSE | AJ23: FALSE | AK23: TRUE | AL23: FALSE
A24: 23 | B24: S0, Normal, No CC, CER | C24: CER | D24: 2000 | E24: 0.025 | F24: NA | G24: NA | H24: UnPooled | I24: CombinationTest | J24: 5 | K24: 2 | L24: list(EP1 = "Binary", EP2 = "Binary") | M24: NA | N24: NA | O24: list(EP1 = c(0.22, 0.22, 0.22, 0.22, 0.22), EP2 = c(0.1, 0.1, 0.1, 0.1, 0.1)) | P24: c(1,1,1,1,1) | Q24: matrix(c(1,0.5,0.5,1),nrow = 2) | R24: c(0.25,0.25,0.25,0.25, 0, 0, 0, 0) | S24: matrix(c(0,1/12,1/12,1/12,3/4,0,0,0, 1/12,0,1/12,1/12,0,3/4,0,0, 1/12,1/12,0,1/12,0,0,3/4,0, 1/12,1/12,1/12,0,0,0,0,3/4, 0,1/3,1/3,1/3,0,0,0,0, 1/3,0,1/3,1/3,0,0,0,0, 1/3,1/3,0,1/3,0,0,0,0, 1/3,1/3,1/3,0,0,0,0,0), nrow = nEps*(nArms-1), byrow = T) | T24: Partly-Parametric | U24: c(1/2,1) | V24: asOF | W24: TRUE | X24: TRUE | Y24: 1 | Z24: 1 | AA24: pvalue | AB24: threshold | AC24: 0.5 | AD24: TRUE | AE24: Selection | AF24: 20000 | AG24: 500 | AH24: Random | AI24: FALSE | AJ24: FALSE | AK24: TRUE | AL24: FALSE
A25: 24 | B25: S0, Aggressive, No CC, CPV | C25: CombPValue | D25: 2000 | E25: 0.025 | F25: NA | G25: NA | H25: UnPooled | I25: CombinationTest | J25: 5 | K25: 2 | L25: list(EP1 = "Binary", EP2 = "Binary") | M25: NA | N25: NA | O25: list(EP1 = c(0.22, 0.22, 0.22, 0.22, 0.22), EP2 = c(0.1, 0.1, 0.1, 0.1, 0.1)) | P25: c(1,1,1,1,1) | Q25: matrix(c(1,0.5,0.5,1),nrow = 2) | R25: c(0.25,0.25,0.25,0.25, 0, 0, 0, 0) | S25: matrix(c(0,1/12,1/12,1/12,3/4,0,0,0, 1/12,0,1/12,1/12,0,3/4,0,0, 1/12,1/12,0,1/12,0,0,3/4,0, 1/12,1/12,1/12,0,0,0,0,3/4, 0,1/3,1/3,1/3,0,0,0,0, 1/3,0,1/3,1/3,0,0,0,0, 1/3,1/3,0,1/3,0,0,0,0, 1/3,1/3,1/3,0,0,0,0,0), nrow = nEps*(nArms-1), byrow = T) | T25: Partly-Parametric | U25: c(1/2,1) | V25: asOF | W25: TRUE | X25: TRUE | Y25: 1 | Z25: 1 | AA25: pvalue | AB25: threshold | AC25: 0.25 | AD25: TRUE | AE25: Selection | AF25: 20000 | AG25: 500 | AH25: Random | AI25: FALSE | AJ25: FALSE | AK25: TRUE | AL25: FALSE
A26: 25 | B26: S0, Aggressive, No CC, CER | C26: CER | D26: 2000 | E26: 0.025 | F26: NA | G26: NA | H26: UnPooled | I26: CombinationTest | J26: 5 | K26: 2 | L26: list(EP1 = "Binary", EP2 = "Binary") | M26: NA | N26: NA | O26: list(EP1 = c(0.22, 0.22, 0.22, 0.22, 0.22), EP2 = c(0.1, 0.1, 0.1, 0.1, 0.1)) | P26: c(1,1,1,1,1) | Q26: matrix(c(1,0.5,0.5,1),nrow = 2) | R26: c(0.25,0.25,0.25,0.25, 0, 0, 0, 0) | S26: matrix(c(0,1/12,1/12,1/12,3/4,0,0,0, 1/12,0,1/12,1/12,0,3/4,0,0, 1/12,1/12,0,1/12,0,0,3/4,0, 1/12,1/12,1/12,0,0,0,0,3/4, 0,1/3,1/3,1/3,0,0,0,0, 1/3,0,1/3,1/3,0,0,0,0, 1/3,1/3,0,1/3,0,0,0,0, 1/3,1/3,1/3,0,0,0,0,0), nrow = nEps*(nArms-1), byrow = T) | T26: Partly-Parametric | U26: c(1/2,1) | V26: asOF | W26: TRUE | X26: TRUE | Y26: 1 | Z26: 1 | AA26: pvalue | AB26: threshold | AC26: 0.25 | AD26: TRUE | AE26: Selection | AF26: 20000 | AG26: 500 | AH26: Random | AI26: FALSE | AJ26: FALSE | AK26: TRUE | AL26: FALSE
A27: 26 | B27: S0, Ultra Aggressive, No CC, CPV | C27: CombPValue | D27: 2000 | E27: 0.025 | F27: NA | G27: NA | H27: UnPooled | I27: CombinationTest | J27: 5 | K27: 2 | L27: list(EP1 = "Binary", EP2 = "Binary") | M27: NA | N27: NA | O27: list(EP1 = c(0.22, 0.22, 0.22, 0.22, 0.22), EP2 = c(0.1, 0.1, 0.1, 0.1, 0.1)) | P27: c(1,1,1,1,1) | Q27: matrix(c(1,0.5,0.5,1),nrow = 2) | R27: c(0.25,0.25,0.25,0.25, 0, 0, 0, 0) | S27: matrix(c(0,1/12,1/12,1/12,3/4,0,0,0, 1/12,0,1/12,1/12,0,3/4,0,0, 1/12,1/12,0,1/12,0,0,3/4,0, 1/12,1/12,1/12,0,0,0,0,3/4, 0,1/3,1/3,1/3,0,0,0,0, 1/3,0,1/3,1/3,0,0,0,0, 1/3,1/3,0,1/3,0,0,0,0, 1/3,1/3,1/3,0,0,0,0,0), nrow = nEps*(nArms-1), byrow = T) | T27: Partly-Parametric | U27: c(1/2,1) | V27: asOF | W27: TRUE | X27: TRUE | Y27: 1 | Z27: 1 | AA27: pvalue | AB27: best | AC27: 1 | AD27: TRUE | AE27: Selection | AF27: 20000 | AG27: 500 | AH27: Random | AI27: FALSE | AJ27: FALSE | AK27: TRUE | AL27: FALSE
A28: 27 | B28: S0, Ultra Aggressive, No CC, CER | C28: CER | D28: 2000 | E28: 0.025 | F28: NA | G28: NA | H28: UnPooled | I28: CombinationTest | J28: 5 | K28: 2 | L28: list(EP1 = "Binary", EP2 = "Binary") | M28: NA | N28: NA | O28: list(EP1 = c(0.22, 0.22, 0.22, 0.22, 0.22), EP2 = c(0.1, 0.1, 0.1, 0.1, 0.1)) | P28: c(1,1,1,1,1) | Q28: matrix(c(1,0.5,0.5,1),nrow = 2) | R28: c(0.25,0.25,0.25,0.25, 0, 0, 0, 0) | S28: matrix(c(0,1/12,1/12,1/12,3/4,0,0,0, 1/12,0,1/12,1/12,0,3/4,0,0, 1/12,1/12,0,1/12,0,0,3/4,0, 1/12,1/12,1/12,0,0,0,0,3/4, 0,1/3,1/3,1/3,0,0,0,0, 1/3,0,1/3,1/3,0,0,0,0, 1/3,1/3,0,1/3,0,0,0,0, 1/3,1/3,1/3,0,0,0,0,0), nrow = nEps*(nArms-1), byrow = T) | T28: Partly-Parametric | U28: c(1/2,1) | V28: asOF | W28: TRUE | X28: TRUE | Y28: 1 | Z28: 1 | AA28: pvalue | AB28: best | AC28: 1 | AD28: TRUE | AE28: Selection | AF28: 20000 | AG28: 500 | AH28: Random | AI28: FALSE | AJ28: FALSE | AK28: TRUE | AL28: FALSE
A29: 28 | B29: S1, No Select, No CC, CPV | C29: CombPValue | D29: 2000 | E29: 0.025 | F29: NA | G29: NA | H29: UnPooled | I29: CombinationTest | J29: 5 | K29: 2 | L29: list(EP1 = "Binary", EP2 = "Binary") | M29: NA | N29: NA | O29: list(EP1 = c(0.1, 0.1, 0.1, 0.1, 0.22), EP2 = c(0.1, 0.1, 0.1, 0.1, 0.22)) | P29: c(1,1,1,1,1) | Q29: matrix(c(1, 0.5, 0.5, 1), byrow = T, nrow = 2) | R29: c(0.25,0.25,0.25,0.25, 0, 0, 0, 0) | S29: matrix(c(0,1/12,1/12,1/12,3/4,0,0,0, 1/12,0,1/12,1/12,0,3/4,0,0, 1/12,1/12,0,1/12,0,0,3/4,0, 1/12,1/12,1/12,0,0,0,0,3/4, 0,1/3,1/3,1/3,0,0,0,0, 1/3,0,1/3,1/3,0,0,0,0, 1/3,1/3,0,1/3,0,0,0,0, 1/3,1/3,1/3,0,0,0,0,0), nrow = nEps*(nArms-1), byrow = T) | T29: Partly-Parametric | U29: c(0.5, 1) | V29: asOF | W29: TRUE | X29: FALSE | Y29: NA | Z29: NA | AA29: NA | AB29: NA | AC29: NA | AD29: NA | AE29: None | AF29: 20000 | AG29: 500 | AH29: Random | AI29: FALSE | AJ29: FALSE | AK29: TRUE | AL29: FALSE
A30: 29 | B30: S1, No Select, No CC, CER | C30: CER | D30: 2000 | E30: 0.025 | F30: NA | G30: NA | H30: UnPooled | I30: CombinationTest | J30: 5 | K30: 2 | L30: list(EP1 = "Binary", EP2 = "Binary") | M30: NA | N30: NA | O30: list(EP1 = c(0.1, 0.1, 0.1, 0.1, 0.22), EP2 = c(0.1, 0.1, 0.1, 0.1, 0.22)) | P30: c(1,1,1,1,1) | Q30: matrix(c(1, 0.5, 0.5, 1), byrow = T, nrow = 2) | R30: c(0.25,0.25,0.25,0.25, 0, 0, 0, 0) | S30: matrix(c(0,1/12,1/12,1/12,3/4,0,0,0, 1/12,0,1/12,1/12,0,3/4,0,0, 1/12,1/12,0,1/12,0,0,3/4,0, 1/12,1/12,1/12,0,0,0,0,3/4, 0,1/3,1/3,1/3,0,0,0,0, 1/3,0,1/3,1/3,0,0,0,0, 1/3,1/3,0,1/3,0,0,0,0, 1/3,1/3,1/3,0,0,0,0,0), nrow = nEps*(nArms-1), byrow = T) | T30: Partly-Parametric | U30: c(0.5, 1) | V30: asOF | W30: TRUE | X30: FALSE | Y30: NA | Z30: NA | AA30: NA | AB30: NA | AC30: NA | AD30: NA | AE30: None | AF30: 20000 | AG30: 500 | AH30: Random | AI30: FALSE | AJ30: FALSE | AK30: TRUE | AL30: FALSE
A31: 30 | B31: S1, Conservative, No CC, CPV | C31: CombPValue | D31: 2000 | E31: 0.025 | F31: NA | G31: NA | H31: UnPooled | I31: CombinationTest | J31: 5 | K31: 2 | L31: list(EP1 = "Binary", EP2 = "Binary") | M31: NA | N31: NA | O31: list(EP1 = c(0.1, 0.1, 0.1, 0.1, 0.22), EP2 = c(0.1, 0.1, 0.1, 0.1, 0.22)) | P31: c(1,1,1,1,1) | Q31: matrix(c(1,0.5,0.5,1),nrow = 2) | R31: c(0.25,0.25,0.25,0.25, 0, 0, 0, 0) | S31: matrix(c(0,1/12,1/12,1/12,3/4,0,0,0, 1/12,0,1/12,1/12,0,3/4,0,0, 1/12,1/12,0,1/12,0,0,3/4,0, 1/12,1/12,1/12,0,0,0,0,3/4, 0,1/3,1/3,1/3,0,0,0,0, 1/3,0,1/3,1/3,0,0,0,0, 1/3,1/3,0,1/3,0,0,0,0, 1/3,1/3,1/3,0,0,0,0,0), nrow = nEps*(nArms-1), byrow = T) | T31: Partly-Parametric | U31: c(1/2,1) | V31: asOF | W31: TRUE | X31: TRUE | Y31: 1 | Z31: 1 | AA31: pvalue | AB31: threshold | AC31: 0.75 | AD31: TRUE | AE31: Selection | AF31: 20000 | AG31: 500 | AH31: Random | AI31: FALSE | AJ31: FALSE | AK31: TRUE | AL31: FALSE
A32: 31 | B32: S1, Conservative, No CC, CER | C32: CER | D32: 2000 | E32: 0.025 | F32: NA | G32: NA | H32: UnPooled | I32: CombinationTest | J32: 5 | K32: 2 | L32: list(EP1 = "Binary", EP2 = "Binary") | M32: NA | N32: NA | O32: list(EP1 = c(0.1, 0.1, 0.1, 0.1, 0.22), EP2 = c(0.1, 0.1, 0.1, 0.1, 0.22)) | P32: c(1,1,1,1,1) | Q32: matrix(c(1,0.5,0.5,1),nrow = 2) | R32: c(0.25,0.25,0.25,0.25, 0, 0, 0, 0) | S32: matrix(c(0,1/12,1/12,1/12,3/4,0,0,0, 1/12,0,1/12,1/12,0,3/4,0,0, 1/12,1/12,0,1/12,0,0,3/4,0, 1/12,1/12,1/12,0,0,0,0,3/4, 0,1/3,1/3,1/3,0,0,0,0, 1/3,0,1/3,1/3,0,0,0,0, 1/3,1/3,0,1/3,0,0,0,0, 1/3,1/3,1/3,0,0,0,0,0), nrow = nEps*(nArms-1), byrow = T) | T32: Partly-Parametric | U32: c(1/2,1) | V32: asOF | W32: TRUE | X32: TRUE | Y32: 1 | Z32: 1 | AA32: pvalue | AB32: threshold | AC32: 0.75 | AD32: TRUE | AE32: Selection | AF32: 20000 | AG32: 500 | AH32: Random | AI32: FALSE | AJ32: FALSE | AK32: TRUE | AL32: FALSE
A33: 32 | B33: S1, Normal, No CC, CPV | C33: CombPValue | D33: 2000 | E33: 0.025 | F33: NA | G33: NA | H33: UnPooled | I33: CombinationTest | J33: 5 | K33: 2 | L33: list(EP1 = "Binary", EP2 = "Binary") | M33: NA | N33: NA | O33: list(EP1 = c(0.1, 0.1, 0.1, 0.1, 0.22), EP2 = c(0.1, 0.1, 0.1, 0.1, 0.22)) | P33: c(1,1,1,1,1) | Q33: matrix(c(1,0.5,0.5,1),nrow = 2) | R33: c(0.25,0.25,0.25,0.25, 0, 0, 0, 0) | S33: matrix(c(0,1/12,1/12,1/12,3/4,0,0,0, 1/12,0,1/12,1/12,0,3/4,0,0, 1/12,1/12,0,1/12,0,0,3/4,0, 1/12,1/12,1/12,0,0,0,0,3/4, 0,1/3,1/3,1/3,0,0,0,0, 1/3,0,1/3,1/3,0,0,0,0, 1/3,1/3,0,1/3,0,0,0,0, 1/3,1/3,1/3,0,0,0,0,0), nrow = nEps*(nArms-1), byrow = T) | T33: Partly-Parametric | U33: c(1/2,1) | V33: asOF | W33: TRUE | X33: TRUE | Y33: 1 | Z33: 1 | AA33: pvalue | AB33: threshold | AC33: 0.5 | AD33: TRUE | AE33: Selection | AF33: 20000 | AG33: 500 | AH33: Random | AI33: FALSE | AJ33: FALSE | AK33: TRUE | AL33: FALSE
A34: 33 | B34: S1, Normal, No CC, CER | C34: CER | D34: 2000 | E34: 0.025 | F34: NA | G34: NA | H34: UnPooled | I34: CombinationTest | J34: 5 | K34: 2 | L34: list(EP1 = "Binary", EP2 = "Binary") | M34: NA | N34: NA | O34: list(EP1 = c(0.1, 0.1, 0.1, 0.1, 0.22), EP2 = c(0.1, 0.1, 0.1, 0.1, 0.22)) | P34: c(1,1,1,1,1) | Q34: matrix(c(1,0.5,0.5,1),nrow = 2) | R34: c(0.25,0.25,0.25,0.25, 0, 0, 0, 0) | S34: matrix(c(0,1/12,1/12,1/12,3/4,0,0,0, 1/12,0,1/12,1/12,0,3/4,0,0, 1/12,1/12,0,1/12,0,0,3/4,0, 1/12,1/12,1/12,0,0,0,0,3/4, 0,1/3,1/3,1/3,0,0,0,0, 1/3,0,1/3,1/3,0,0,0,0, 1/3,1/3,0,1/3,0,0,0,0, 1/3,1/3,1/3,0,0,0,0,0), nrow = nEps*(nArms-1), byrow = T) | T34: Partly-Parametric | U34: c(1/2,1) | V34: asOF | W34: TRUE | X34: TRUE | Y34: 1 | Z34: 1 | AA34: pvalue | AB34: threshold | AC34: 0.5 | AD34: TRUE | AE34: Selection | AF34: 20000 | AG34: 500 | AH34: Random | AI34: FALSE | AJ34: FALSE | AK34: TRUE | AL34: FALSE
A35: 34 | B35: S1, Aggressive, No CC, CPV | C35: CombPValue | D35: 2000 | E35: 0.025 | F35: NA | G35: NA | H35: UnPooled | I35: CombinationTest | J35: 5 | K35: 2 | L35: list(EP1 = "Binary", EP2 = "Binary") | M35: NA | N35: NA | O35: list(EP1 = c(0.1, 0.1, 0.1, 0.1, 0.22), EP2 = c(0.1, 0.1, 0.1, 0.1, 0.22)) | P35: c(1,1,1,1,1) | Q35: matrix(c(1,0.5,0.5,1),nrow = 2) | R35: c(0.25,0.25,0.25,0.25, 0, 0, 0, 0) | S35: matrix(c(0,1/12,1/12,1/12,3/4,0,0,0, 1/12,0,1/12,1/12,0,3/4,0,0, 1/12,1/12,0,1/12,0,0,3/4,0, 1/12,1/12,1/12,0,0,0,0,3/4, 0,1/3,1/3,1/3,0,0,0,0, 1/3,0,1/3,1/3,0,0,0,0, 1/3,1/3,0,1/3,0,0,0,0, 1/3,1/3,1/3,0,0,0,0,0), nrow = nEps*(nArms-1), byrow = T) | T35: Partly-Parametric | U35: c(1/2,1) | V35: asOF | W35: TRUE | X35: TRUE | Y35: 1 | Z35: 1 | AA35: pvalue | AB35: threshold | AC35: 0.25 | AD35: TRUE | AE35: Selection | AF35: 20000 | AG35: 500 | AH35: Random | AI35: FALSE | AJ35: FALSE | AK35: TRUE | AL35: FALSE
A36: 35 | B36: S1, Aggressive, No CC, CER | C36: CER | D36: 2000 | E36: 0.025 | F36: NA | G36: NA | H36: UnPooled | I36: CombinationTest | J36: 5 | K36: 2 | L36: list(EP1 = "Binary", EP2 = "Binary") | M36: NA | N36: NA | O36: list(EP1 = c(0.1, 0.1, 0.1, 0.1, 0.22), EP2 = c(0.1, 0.1, 0.1, 0.1, 0.22)) | P36: c(1,1,1,1,1) | Q36: matrix(c(1,0.5,0.5,1),nrow = 2) | R36: c(0.25,0.25,0.25,0.25, 0, 0, 0, 0) | S36: matrix(c(0,1/12,1/12,1/12,3/4,0,0,0, 1/12,0,1/12,1/12,0,3/4,0,0, 1/12,1/12,0,1/12,0,0,3/4,0, 1/12,1/12,1/12,0,0,0,0,3/4, 0,1/3,1/3,1/3,0,0,0,0, 1/3,0,1/3,1/3,0,0,0,0, 1/3,1/3,0,1/3,0,0,0,0, 1/3,1/3,1/3,0,0,0,0,0), nrow = nEps*(nArms-1), byrow = T) | T36: Partly-Parametric | U36: c(1/2,1) | V36: asOF | W36: TRUE | X36: TRUE | Y36: 1 | Z36: 1 | AA36: pvalue | AB36: threshold | AC36: 0.25 | AD36: TRUE | AE36: Selection | AF36: 20000 | AG36: 500 | AH36: Random | AI36: FALSE | AJ36: FALSE | AK36: TRUE | AL36: FALSE
A37: 36 | B37: S1, Ultra Aggressive, No CC, CPV | C37: CombPValue | D37: 2000 | E37: 0.025 | F37: NA | G37: NA | H37: UnPooled | I37: CombinationTest | J37: 5 | K37: 2 | L37: list(EP1 = "Binary", EP2 = "Binary") | M37: NA | N37: NA | O37: list(EP1 = c(0.1, 0.1, 0.1, 0.1, 0.22), EP2 = c(0.1, 0.1, 0.1, 0.1, 0.22)) | P37: c(1,1,1,1,1) | Q37: matrix(c(1,0.5,0.5,1),nrow = 2) | R37: c(0.25,0.25,0.25,0.25, 0, 0, 0, 0) | S37: matrix(c(0,1/12,1/12,1/12,3/4,0,0,0, 1/12,0,1/12,1/12,0,3/4,0,0, 1/12,1/12,0,1/12,0,0,3/4,0, 1/12,1/12,1/12,0,0,0,0,3/4, 0,1/3,1/3,1/3,0,0,0,0, 1/3,0,1/3,1/3,0,0,0,0, 1/3,1/3,0,1/3,0,0,0,0, 1/3,1/3,1/3,0,0,0,0,0), nrow = nEps*(nArms-1), byrow = T) | T37: Partly-Parametric | U37: c(1/2,1) | V37: asOF | W37: TRUE | X37: TRUE | Y37: 1 | Z37: 1 | AA37: pvalue | AB37: best | AC37: 1 | AD37: TRUE | AE37: Selection | AF37: 20000 | AG37: 500 | AH37: Random | AI37: FALSE | AJ37: FALSE | AK37: TRUE | AL37: FALSE
A38: 37 | B38: S1, Ultra Aggressive, No CC, CER | C38: CER | D38: 2000 | E38: 0.025 | F38: NA | G38: NA | H38: UnPooled | I38: CombinationTest | J38: 5 | K38: 2 | L38: list(EP1 = "Binary", EP2 = "Binary") | M38: NA | N38: NA | O38: list(EP1 = c(0.1, 0.1, 0.1, 0.1, 0.22), EP2 = c(0.1, 0.1, 0.1, 0.1, 0.22)) | P38: c(1,1,1,1,1) | Q38: matrix(c(1,0.5,0.5,1),nrow = 2) | R38: c(0.25,0.25,0.25,0.25, 0, 0, 0, 0) | S38: matrix(c(0,1/12,1/12,1/12,3/4,0,0,0, 1/12,0,1/12,1/12,0,3/4,0,0, 1/12,1/12,0,1/12,0,0,3/4,0, 1/12,1/12,1/12,0,0,0,0,3/4, 0,1/3,1/3,1/3,0,0,0,0, 1/3,0,1/3,1/3,0,0,0,0, 1/3,1/3,0,1/3,0,0,0,0, 1/3,1/3,1/3,0,0,0,0,0), nrow = nEps*(nArms-1), byrow = T) | T38: Partly-Parametric | U38: c(1/2,1) | V38: asOF | W38: TRUE | X38: TRUE | Y38: 1 | Z38: 1 | AA38: pvalue | AB38: best | AC38: 1 | AD38: TRUE | AE38: Selection | AF38: 20000 | AG38: 500 | AH38: Random | AI38: FALSE | AJ38: FALSE | AK38: TRUE | AL38: FALSE
A39: 38 | B39: S2, No Select, No CC, CPV | C39: CombPValue | D39: 2000 | E39: 0.025 | F39: NA | G39: NA | H39: UnPooled | I39: CombinationTest | J39: 5 | K39: 2 | L39: list(EP1 = "Binary", EP2 = "Binary") | M39: NA | N39: NA | O39: list(EP1 = c(0.1, 0.1, 0.1, 0.22, 0.22), EP2 = c(0.1, 0.1, 0.1, 0.22, 0.22)) | P39: c(1,1,1,1,1) | Q39: matrix(c(1, 0.5, 0.5, 1), byrow = T, nrow = 2) | R39: c(0.25,0.25,0.25,0.25, 0, 0, 0, 0) | S39: matrix(c(0,1/12,1/12,1/12,3/4,0,0,0, 1/12,0,1/12,1/12,0,3/4,0,0, 1/12,1/12,0,1/12,0,0,3/4,0, 1/12,1/12,1/12,0,0,0,0,3/4, 0,1/3,1/3,1/3,0,0,0,0, 1/3,0,1/3,1/3,0,0,0,0, 1/3,1/3,0,1/3,0,0,0,0, 1/3,1/3,1/3,0,0,0,0,0), nrow = nEps*(nArms-1), byrow = T) | T39: Partly-Parametric | U39: c(0.5, 1) | V39: asOF | W39: TRUE | X39: FALSE | Y39: NA | Z39: NA | AA39: NA | AB39: NA | AC39: NA | AD39: NA | AE39: None | AF39: 20000 | AG39: 500 | AH39: Random | AI39: FALSE | AJ39: FALSE | AK39: TRUE | AL39: FALSE
A40: 39 | B40: S2, No Select, No CC, CER | C40: CER | D40: 2000 | E40: 0.025 | F40: NA | G40: NA | H40: UnPooled | I40: CombinationTest | J40: 5 | K40: 2 | L40: list(EP1 = "Binary", EP2 = "Binary") | M40: NA | N40: NA | O40: list(EP1 = c(0.1, 0.1, 0.1, 0.22, 0.22), EP2 = c(0.1, 0.1, 0.1, 0.22, 0.22)) | P40: c(1,1,1,1,1) | Q40: matrix(c(1, 0.5, 0.5, 1), byrow = T, nrow = 2) | R40: c(0.25,0.25,0.25,0.25, 0, 0, 0, 0) | S40: matrix(c(0,1/12,1/12,1/12,3/4,0,0,0, 1/12,0,1/12,1/12,0,3/4,0,0, 1/12,1/12,0,1/12,0,0,3/4,0, 1/12,1/12,1/12,0,0,0,0,3/4, 0,1/3,1/3,1/3,0,0,0,0, 1/3,0,1/3,1/3,0,0,0,0, 1/3,1/3,0,1/3,0,0,0,0, 1/3,1/3,1/3,0,0,0,0,0), nrow = nEps*(nArms-1), byrow = T) | T40: Partly-Parametric | U40: c(0.5, 1) | V40: asOF | W40: TRUE | X40: FALSE | Y40: NA | Z40: NA | AA40: NA | AB40: NA | AC40: NA | AD40: NA | AE40: None | AF40: 20000 | AG40: 500 | AH40: Random | AI40: FALSE | AJ40: FALSE | AK40: TRUE | AL40: FALSE
...

Sheet OutCERBin2eps3arms
F1: x | P1: x | Q1: x | BC1: Added cols >>>
A2: ModelID | B2: Scenario | C2: seed | D2: Global.Power | E2: Conjunctive.Power | F2: Disjunctive.Power | G2: FWER | H2: CI_95perc_Global.Power | I2: CI_95perc_Conjunctive.Power | J2: CI_95perc_Disjunctive.Power | K2: CI_95perc_FWER | L2: StagewiseRejection_Count | M2: StagewiseRejection_Percentage | N2: HoursTaken | O2: Input | P2: Method | Q2: SampleSize | R2: alpha | S2: TestStatCont | T2: CommonStdDev | U2: TestStatBin | V2: FWERControl | W2: nArms | X2: nEps | Y2: lEpType | Z2: Arms.Mean | AA2: Arms.std.dev | AB2: Arms.Prop | AC2: Arms.alloc.ratio | AD2: EP.Corr | AE2: WI | AF2: G | AG2: test.type | AH2: info_frac | AI2: typeOfDesign | AJ2: MultipleWinners | AK2: Selection | AL2: SelectionLook | AM2: SelectEndPoint | AN2: SelectionScale | AO2: SelectionCriterion | AP2: SelectionParmeter | AQ2: KeepAssosiatedEps | AR2: ImplicitSSR | AS2: nSimulation | AT2: nSimulation_Stage2 | AU2: Seed2 | AV2: SummaryStat | AW2: plotGraphs | AX2: Parallel | AY2: UseCC | AZ2: Matching.Pair | BA2: Test.Suite | BB2: Compare.Set | BC2: Treat.Sel.Rule | BD2: Alt.Scen | BE2: Glob.Pow% | BF2: Conj.Pow% | BG2: Disj.Pow% | BH2: FWER% | BI2: LCL_Glob.Pow% | BJ2: UCL_Glob.Pow% | BK2: LCL_Conj.Pow% | BL2: UCL_Conj.Pow% | BM2: LCL_Disj.Pow% | BN2: UCL_Disj.Pow% | BO2: LCL_FWER% | BP2: UCL_FWER% | BQ2: DP.CI | BR2: CP.CI | BS2: FW.CI
A3: 1 | B3: No drop, Partly-Parametric | C3: 1234 | D3: 0.02587615 | E3: 0 | F3: 0 | G3: 0.02587615 | H3: (0.02496,0.02679) | I3: (0,0) | J3: (0,0) | K3: (0.02496,0.02679) | L3: 38478 | M3: 0.0019,0.0239 | N3: 2.3855488 | O3: >>> | P3: CER | Q3: 600 | R3: 0.025 | S3: NA | T3: NA | U3: UnPooled | V3: CombinationTest | W3: 3 | X3: 2 | Y3: list('EP1' = 'Binary', 'EP2' = 'Binary') | Z3: NA | AA3: NA | AB3: list('EP1' = c(0.4, 0.4, 0.4), 'EP2' = c(0.5, 0.5, 0.5)) | AC3: c(1,1,1) | AD3: matrix(c(1, 0.5, 0.5, 1), nrow = nEps) # c(1) | AE3: c(rep(1/4, 4)) | AF3: rbind(H1=c(0, 1/3, 1/3, 1/3), H2=c(1/3, 0, 1/3, 1/3), H3=c(1/3, 1/3, 0, 1/3), H4=c(1/3, 1/3, 1/3, 0)) | AG3: Partly-Parametric | AH3: c(0.5, 1) | AI3: asOF | AJ3: FALSE | AK3: FALSE | AL3: NA | AM3: NA | AN3: NA | AO3: NA | AP3: NA | AQ3: NA | AR3: None | AS3: 20000 | AT3: 2000 | AU3: 1234 | AV3: TRUE | AW3: FALSE | AX3: TRUE | AY3: TRUE | AZ3: NA | BA3: =INDEX(Inp_CER_Bin_2eps3arms!$AN$2:$AN$176,MATCH(Table1[[#This Row],[ModelID]],Inp_CER_Bin_2eps3arms!$A$2:$A$176,0)) -> 0 | BB3: NA | BC3: No drop | BD3: S0 | BE3: =Table1[[#This Row],[Global.Power]] -> 0.02587615 | BF3: =Table1[[#This Row],[Conjunctive.Power]] -> 0 | BG3: =Table1[[#This Row],[Disjunctive.Power]] -> 0 | BH3: =Table1[[#This Row],[FWER]] -> 0.02587615 | BI3: =_xlfn.NUMBERVALUE(MID(Table1[[#This Row],[CI_95perc_Global.Power]],2,FIND(",",Table1[[#This Row],[CI_95perc_Global.Power]])-2)) -> 0.02496 | BJ3: =_xlfn.NUMBERVALUE(MID(Table1[[#This Row],[CI_95perc_Global.Power]],FIND(",",Table1[[#This Row],[CI_95perc_Global.Power]])+1,LEN(Table1[[#This Row],[CI_95perc_Global.Power]])-FIND(",",Table1[[#This Row],[CI_95perc_Global.Power]])-1)) -> 0.02679 | BK3: =_xlfn.NUMBERVALUE(MID(Table1[[#This Row],[CI_95perc_Conjunctive.Power]],2,FIND(",",Table1[[#This Row],[CI_95perc_Conjunctive.Power]])-2)) -> 0 | BL3: =_xlfn.NUMBERVALUE(MID(Table1[[#This Row],[CI_95perc_Conjunctive.Power]],FIND(",",Table1[[#This Row],[CI_95perc_Conjunctive.Power]])+1,LEN(Table1[[#This Row],[CI_95perc_Conjunctive.Power]])-FIND(",",Table1[[#This Row],[CI_95perc_Conjunctive.Power]])-1)) -> 0 | BM3: =_xlfn.NUMBERVALUE(MID(Table1[[#This Row],[CI_95perc_Disjunctive.Power]],2,FIND(",",Table1[[#This Row],[CI_95perc_Disjunctive.Power]])-2)) -> 0 | BN3: =_xlfn.NUMBERVALUE(MID(Table1[[#This Row],[CI_95perc_Disjunctive.Power]],FIND(",",Table1[[#This Row],[CI_95perc_Disjunctive.Power]])+1,LEN(Table1[[#This Row],[CI_95perc_Disjunctive.Power]])-FIND(",",Table1[[#This Row],[CI_95perc_Disjunctive.Power]])-1)) -> 0 | BO3: =_xlfn.NUMBERVALUE(MID(Table1[[#This Row],[CI_95perc_FWER]],2,FIND(",",Table1[[#This Row],[CI_95perc_FWER]])-2)) -> 0.02496 | BP3: =_xlfn.NUMBERVALUE(MID(Table1[[#This Row],[CI_95perc_FWER]],FIND(",",Table1[[#This Row],[CI_95perc_FWER]])+1,LEN(Table1[[#This Row],[CI_95perc_FWER]])-FIND(",",Table1[[#This Row],[CI_95perc_FWER]])-1)) -> 0.02679 | BQ3: =_xlfn.CONCAT("(",TEXT(Table1[[#This Row],[LCL_Disj.Pow%]],"0.00%"), ", ",TEXT(Table1[[#This Row],[UCL_Disj.Pow%]],"0.00%"),")") -> (0.00%, 0.00%) | BR3: =_xlfn.CONCAT("(",TEXT(Table1[[#This Row],[LCL_Conj.Pow%]],"0.00%"),", ",TEXT(Table1[[#This Row],[UCL_Conj.Pow%]],"0.00%"),")") -> (0.00%, 0.00%) | BS3: =_xlfn.CONCAT("(",TEXT(Table1[[#This Row],[LCL_FWER%]],"0.00%"),", ",TEXT(Table1[[#This Row],[UCL_FWER%]],"0.00%"),")") -> (2.50%, 2.68%)
A4: 2 | B4: No drop, Partly-Parametric | C4: 1234 | D4: 0.0246273 | E4: 0 | F4: 0 | G4: 0.0246273 | H4: (0.02372,0.02554) | I4: (0,0) | J4: (0,0) | K4: (0.02372,0.02554) | L4: 41417 | M4: 0.00205,0.02085 | N4: 2.6200346 | O4: >>> | P4: CER | Q4: 1500 | R4: 0.025 | S4: NA | T4: NA | U4: UnPooled | V4: CombinationTest | W4: 3 | X4: 2 | Y4: list('EP1' = 'Binary', 'EP2' = 'Binary') | Z4: NA | AA4: NA | AB4: list('EP1' = c(0.4, 0.4, 0.4), 'EP2' = c(0.5, 0.5, 0.5)) | AC4: c(1,1,1) | AD4: matrix(c(1, 0.5, 0.5, 1), nrow = nEps) # c(1) | AE4: c(rep(1/4, 4)) | AF4: rbind(H1=c(0, 1/3, 1/3, 1/3), H2=c(1/3, 0, 1/3, 1/3), H3=c(1/3, 1/3, 0, 1/3), H4=c(1/3, 1/3, 1/3, 0)) | AG4: Partly-Parametric | AH4: c(0.5, 1) | AI4: asOF | AJ4: FALSE | AK4: FALSE | AL4: NA | AM4: NA | AN4: NA | AO4: NA | AP4: NA | AQ4: NA | AR4: None | AS4: 20000 | AT4: 2000 | AU4: 1234 | AV4: TRUE | AW4: FALSE | AX4: TRUE | AY4: TRUE | AZ4: NA | BA4: =INDEX(Inp_CER_Bin_2eps3arms!$AN$2:$AN$176,MATCH(Table1[[#This Row],[ModelID]],Inp_CER_Bin_2eps3arms!$A$2:$A$176,0)) -> 0 | BB4: NA | BC4: No drop | BD4: S0 | BE4: =Table1[[#This Row],[Global.Power]] -> 0.0246273 | BF4: =Table1[[#This Row],[Conjunctive.Power]] -> 0 | BG4: =Table1[[#This Row],[Disjunctive.Power]] -> 0 | BH4: =Table1[[#This Row],[FWER]] -> 0.0246273 | BI4: =_xlfn.NUMBERVALUE(MID(Table1[[#This Row],[CI_95perc_Global.Power]],2,FIND(",",Table1[[#This Row],[CI_95perc_Global.Power]])-2)) -> 0.02372 | BJ4: =_xlfn.NUMBERVALUE(MID(Table1[[#This Row],[CI_95perc_Global.Power]],FIND(",",Table1[[#This Row],[CI_95perc_Global.Power]])+1,LEN(Table1[[#This Row],[CI_95perc_Global.Power]])-FIND(",",Table1[[#This Row],[CI_95perc_Global.Power]])-1)) -> 0.02554 | BK4: =_xlfn.NUMBERVALUE(MID(Table1[[#This Row],[CI_95perc_Conjunctive.Power]],2,FIND(",",Table1[[#This Row],[CI_95perc_Conjunctive.Power]])-2)) -> 0 | BL4: =_xlfn.NUMBERVALUE(MID(Table1[[#This Row],[CI_95perc_Conjunctive.Power]],FIND(",",Table1[[#This Row],[CI_95perc_Conjunctive.Power]])+1,LEN(Table1[[#This Row],[CI_95perc_Conjunctive.Power]])-FIND(",",Table1[[#This Row],[CI_95perc_Conjunctive.Power]])-1)) -> 0 | BM4: =_xlfn.NUMBERVALUE(MID(Table1[[#This Row],[CI_95perc_Disjunctive.Power]],2,FIND(",",Table1[[#This Row],[CI_95perc_Disjunctive.Power]])-2)) -> 0 | BN4: =_xlfn.NUMBERVALUE(MID(Table1[[#This Row],[CI_95perc_Disjunctive.Power]],FIND(",",Table1[[#This Row],[CI_95perc_Disjunctive.Power]])+1,LEN(Table1[[#This Row],[CI_95perc_Disjunctive.Power]])-FIND(",",Table1[[#This Row],[CI_95perc_Disjunctive.Power]])-1)) -> 0 | BO4: =_xlfn.NUMBERVALUE(MID(Table1[[#This Row],[CI_95perc_FWER]],2,FIND(",",Table1[[#This Row],[CI_95perc_FWER]])-2)) -> 0.02372 | BP4: =_xlfn.NUMBERVALUE(MID(Table1[[#This Row],[CI_95perc_FWER]],FIND(",",Table1[[#This Row],[CI_95perc_FWER]])+1,LEN(Table1[[#This Row],[CI_95perc_FWER]])-FIND(",",Table1[[#This Row],[CI_95perc_FWER]])-1)) -> 0.02554 | BQ4: =_xlfn.CONCAT("(",TEXT(Table1[[#This Row],[LCL_Disj.Pow%]],"0.00%"), ", ",TEXT(Table1[[#This Row],[UCL_Disj.Pow%]],"0.00%"),")") -> (0.00%, 0.00%) | BR4: =_xlfn.CONCAT("(",TEXT(Table1[[#This Row],[LCL_Conj.Pow%]],"0.00%"),", ",TEXT(Table1[[#This Row],[UCL_Conj.Pow%]],"0.00%"),")") -> (0.00%, 0.00%) | BS4: =_xlfn.CONCAT("(",TEXT(Table1[[#This Row],[LCL_FWER%]],"0.00%"),", ",TEXT(Table1[[#This Row],[UCL_FWER%]],"0.00%"),")") -> (2.37%, 2.55%)
A5: 3 | B5: No drop, Partly-Parametric | C5: 1234 | D5: 0.024870175 | E5: 0 | F5: 0 | G5: 0.024870175 | H5: (0.02396,0.02578) | I5: (0,0) | J5: (0,0) | K5: (0.02396,0.02578) | L5: 40466 | M5: 0.002,0.0233 | N5: 2.9317936 | O5: >>> | P5: CER | Q5: 3000 | R5: 0.025 | S5: NA | T5: NA | U5: UnPooled | V5: CombinationTest | W5: 3 | X5: 2 | Y5: list('EP1' = 'Binary', 'EP2' = 'Binary') | Z5: NA | AA5: NA | AB5: list('EP1' = c(0.4, 0.4, 0.4), 'EP2' = c(0.5, 0.5, 0.5)) | AC5: c(1,1,1) | AD5: matrix(c(1, 0.5, 0.5, 1), nrow = nEps) # c(1) | AE5: c(rep(1/4, 4)) | AF5: rbind(H1=c(0, 1/3, 1/3, 1/3), H2=c(1/3, 0, 1/3, 1/3), H3=c(1/3, 1/3, 0, 1/3), H4=c(1/3, 1/3, 1/3, 0)) | AG5: Partly-Parametric | AH5: c(0.5, 1) | AI5: asOF | AJ5: FALSE | AK5: FALSE | AL5: NA | AM5: NA | AN5: NA | AO5: NA | AP5: NA | AQ5: NA | AR5: None | AS5: 20000 | AT5: 2000 | AU5: 1234 | AV5: TRUE | AW5: FALSE | AX5: TRUE | AY5: TRUE | AZ5: NA | BA5: =INDEX(Inp_CER_Bin_2eps3arms!$AN$2:$AN$176,MATCH(Table1[[#This Row],[ModelID]],Inp_CER_Bin_2eps3arms!$A$2:$A$176,0)) -> 0 | BB5: NA | BC5: No drop | BD5: S0 | BE5: =Table1[[#This Row],[Global.Power]] -> 0.024870175 | BF5: =Table1[[#This Row],[Conjunctive.Power]] -> 0 | BG5: =Table1[[#This Row],[Disjunctive.Power]] -> 0 | BH5: =Table1[[#This Row],[FWER]] -> 0.024870175 | BI5: =_xlfn.NUMBERVALUE(MID(Table1[[#This Row],[CI_95perc_Global.Power]],2,FIND(",",Table1[[#This Row],[CI_95perc_Global.Power]])-2)) -> 0.02396 | BJ5: =_xlfn.NUMBERVALUE(MID(Table1[[#This Row],[CI_95perc_Global.Power]],FIND(",",Table1[[#This Row],[CI_95perc_Global.Power]])+1,LEN(Table1[[#This Row],[CI_95perc_Global.Power]])-FIND(",",Table1[[#This Row],[CI_95perc_Global.Power]])-1)) -> 0.02578 | BK5: =_xlfn.NUMBERVALUE(MID(Table1[[#This Row],[CI_95perc_Conjunctive.Power]],2,FIND(",",Table1[[#This Row],[CI_95perc_Conjunctive.Power]])-2)) -> 0 | BL5: =_xlfn.NUMBERVALUE(MID(Table1[[#This Row],[CI_95perc_Conjunctive.Power]],FIND(",",Table1[[#This Row],[CI_95perc_Conjunctive.Power]])+1,LEN(Table1[[#This Row],[CI_95perc_Conjunctive.Power]])-FIND(",",Table1[[#This Row],[CI_95perc_Conjunctive.Power]])-1)) -> 0 | BM5: =_xlfn.NUMBERVALUE(MID(Table1[[#This Row],[CI_95perc_Disjunctive.Power]],2,FIND(",",Table1[[#This Row],[CI_95perc_Disjunctive.Power]])-2)) -> 0 | BN5: =_xlfn.NUMBERVALUE(MID(Table1[[#This Row],[CI_95perc_Disjunctive.Power]],FIND(",",Table1[[#This Row],[CI_95perc_Disjunctive.Power]])+1,LEN(Table1[[#This Row],[CI_95perc_Disjunctive.Power]])-FIND(",",Table1[[#This Row],[CI_95perc_Disjunctive.Power]])-1)) -> 0 | BO5: =_xlfn.NUMBERVALUE(MID(Table1[[#This Row],[CI_95perc_FWER]],2,FIND(",",Table1[[#This Row],[CI_95perc_FWER]])-2)) -> 0.02396 | BP5: =_xlfn.NUMBERVALUE(MID(Table1[[#This Row],[CI_95perc_FWER]],FIND(",",Table1[[#This Row],[CI_95perc_FWER]])+1,LEN(Table1[[#This Row],[CI_95perc_FWER]])-FIND(",",Table1[[#This Row],[CI_95perc_FWER]])-1)) -> 0.02578 | BQ5: =_xlfn.CONCAT("(",TEXT(Table1[[#This Row],[LCL_Disj.Pow%]],"0.00%"), ", ",TEXT(Table1[[#This Row],[UCL_Disj.Pow%]],"0.00%"),")") -> (0.00%, 0.00%) | BR5: =_xlfn.CONCAT("(",TEXT(Table1[[#This Row],[LCL_Conj.Pow%]],"0.00%"),", ",TEXT(Table1[[#This Row],[UCL_Conj.Pow%]],"0.00%"),")") -> (0.00%, 0.00%) | BS5: =_xlfn.CONCAT("(",TEXT(Table1[[#This Row],[LCL_FWER%]],"0.00%"),", ",TEXT(Table1[[#This Row],[UCL_FWER%]],"0.00%"),")") -> (2.40%, 2.58%)
A6: 4 | B6: No drop, Partly-Parametric | C6: 1234 | D6: 0.02444845 | E6: 0 | F6: 0 | G6: 0.02444845 | H6: (0.02359,0.02531) | I6: (0,0) | J6: (0,0) | K6: (0.02359,0.02531) | L6: 31486 | M6: 0.00155,0.0243 | N6: 3.3871573 | O6: >>> | P6: CER | Q6: 5000 | R6: 0.025 | S6: NA | T6: NA | U6: UnPooled | V6: CombinationTest | W6: 3 | X6: 2 | Y6: list('EP1' = 'Binary', 'EP2' = 'Binary') | Z6: NA | AA6: NA | AB6: list('EP1' = c(0.4, 0.4, 0.4), 'EP2' = c(0.5, 0.5, 0.5)) | AC6: c(1,1,1) | AD6: matrix(c(1, 0.5, 0.5, 1), nrow = nEps) # c(1) | AE6: c(rep(1/4, 4)) | AF6: rbind(H1=c(0, 1/3, 1/3, 1/3), H2=c(1/3, 0, 1/3, 1/3), H3=c(1/3, 1/3, 0, 1/3), H4=c(1/3, 1/3, 1/3, 0)) | AG6: Partly-Parametric | AH6: c(0.5, 1) | AI6: asOF | AJ6: FALSE | AK6: FALSE | AL6: NA | AM6: NA | AN6: NA | AO6: NA | AP6: NA | AQ6: NA | AR6: None | AS6: 20000 | AT6: 2000 | AU6: 1234 | AV6: TRUE | AW6: FALSE | AX6: TRUE | AY6: TRUE | AZ6: NA | BA6: =INDEX(Inp_CER_Bin_2eps3arms!$AN$2:$AN$176,MATCH(Table1[[#This Row],[ModelID]],Inp_CER_Bin_2eps3arms!$A$2:$A$176,0)) -> 0 | BB6: NA | BC6: No drop | BD6: S0 | BE6: =Table1[[#This Row],[Global.Power]] -> 0.02444845 | BF6: =Table1[[#This Row],[Conjunctive.Power]] -> 0 | BG6: =Table1[[#This Row],[Disjunctive.Power]] -> 0 | BH6: =Table1[[#This Row],[FWER]] -> 0.02444845 | BI6: =_xlfn.NUMBERVALUE(MID(Table1[[#This Row],[CI_95perc_Global.Power]],2,FIND(",",Table1[[#This Row],[CI_95perc_Global.Power]])-2)) -> 0.02359 | BJ6: =_xlfn.NUMBERVALUE(MID(Table1[[#This Row],[CI_95perc_Global.Power]],FIND(",",Table1[[#This Row],[CI_95perc_Global.Power]])+1,LEN(Table1[[#This Row],[CI_95perc_Global.Power]])-FIND(",",Table1[[#This Row],[CI_95perc_Global.Power]])-1)) -> 0.02531 | BK6: =_xlfn.NUMBERVALUE(MID(Table1[[#This Row],[CI_95perc_Conjunctive.Power]],2,FIND(",",Table1[[#This Row],[CI_95perc_Conjunctive.Power]])-2)) -> 0 | BL6: =_xlfn.NUMBERVALUE(MID(Table1[[#This Row],[CI_95perc_Conjunctive.Power]],FIND(",",Table1[[#This Row],[CI_95perc_Conjunctive.Power]])+1,LEN(Table1[[#This Row],[CI_95perc_Conjunctive.Power]])-FIND(",",Table1[[#This Row],[CI_95perc_Conjunctive.Power]])-1)) -> 0 | BM6: =_xlfn.NUMBERVALUE(MID(Table1[[#This Row],[CI_95perc_Disjunctive.Power]],2,FIND(",",Table1[[#This Row],[CI_95perc_Disjunctive.Power]])-2)) -> 0 | BN6: =_xlfn.NUMBERVALUE(MID(Table1[[#This Row],[CI_95perc_Disjunctive.Power]],FIND(",",Table1[[#This Row],[CI_95perc_Disjunctive.Power]])+1,LEN(Table1[[#This Row],[CI_95perc_Disjunctive.Power]])-FIND(",",Table1[[#This Row],[CI_95perc_Disjunctive.Power]])-1)) -> 0 | BO6: =_xlfn.NUMBERVALUE(MID(Table1[[#This Row],[CI_95perc_FWER]],2,FIND(",",Table1[[#This Row],[CI_95perc_FWER]])-2)) -> 0.02359 | BP6: =_xlfn.NUMBERVALUE(MID(Table1[[#This Row],[CI_95perc_FWER]],FIND(",",Table1[[#This Row],[CI_95perc_FWER]])+1,LEN(Table1[[#This Row],[CI_95perc_FWER]])-FIND(",",Table1[[#This Row],[CI_95perc_FWER]])-1)) -> 0.02531 | BQ6: =_xlfn.CONCAT("(",TEXT(Table1[[#This Row],[LCL_Disj.Pow%]],"0.00%"), ", ",TEXT(Table1[[#This Row],[UCL_Disj.Pow%]],"0.00%"),")") -> (0.00%, 0.00%) | BR6: =_xlfn.CONCAT("(",TEXT(Table1[[#This Row],[LCL_Conj.Pow%]],"0.00%"),", ",TEXT(Table1[[#This Row],[UCL_Conj.Pow%]],"0.00%"),")") -> (0.00%, 0.00%) | BS6: =_xlfn.CONCAT("(",TEXT(Table1[[#This Row],[LCL_FWER%]],"0.00%"),", ",TEXT(Table1[[#This Row],[UCL_FWER%]],"0.00%"),")") -> (2.36%, 2.53%)
A7: 5 | B7: Fut=0.25,N=600,MultWin=F | C7: 745664 | D7: 0.0190639 | E7: 0 | F7: 0 | G7: 0.0190639 | H7: (0.01822,0.01991) | I7: (0,0) | J7: (0,0) | K7: (0.01822,0.01991) | L7: 32317 | M7: 0.0016,0.01585 | N7: 0.84097805 | O7: >>> | P7: CER | Q7: 600 | R7: 0.025 | S7: NA | T7: NA | U7: UnPooled | V7: CombinationTest | W7: 3 | X7: 2 | Y7: list('EP1' = 'Binary', 'EP2' = 'Binary') | Z7: NA | AA7: NA | AB7: list('EP1' = c(0.4, 0.4, 0.4), 'EP2' = c(0.5, 0.5, 0.5)) | AC7: c(1,1,1) | AD7: matrix(c(1, 0.5, 0.5, 1), nrow = nEps) # c(1) | AE7: c(rep(1/4, 4)) | AF7: rbind(H1=c(0, 1/3, 1/3, 1/3), H2=c(1/3, 0, 1/3, 1/3), H3=c(1/3, 1/3, 0, 1/3), H4=c(1/3, 1/3, 1/3, 0)) | AG7: Partly-Parametric | AH7: c(0.5, 1) | AI7: asOF | AJ7: FALSE | AK7: TRUE | AL7: 1 | AM7: 1 | AN7: pvalue | AO7: threshold | AP7: 0.25 | AQ7: TRUE | AR7: Selection | AS7: 20000 | AT7: 2000 | AU7: 745664 | AV7: TRUE | AW7: FALSE | AX7: TRUE | AY7: TRUE | AZ7: NA | BA7: =INDEX(Inp_CER_Bin_2eps3arms!$AN$2:$AN$176,MATCH(Table1[[#This Row],[ModelID]],Inp_CER_Bin_2eps3arms!$A$2:$A$176,0)) -> 0 | BB7: NA | BC7: Aggressive | BD7: S0 | BE7: =Table1[[#This Row],[Global.Power]] -> 0.0190639 | BF7: =Table1[[#This Row],[Conjunctive.Power]] -> 0 | BG7: =Table1[[#This Row],[Disjunctive.Power]] -> 0 | BH7: =Table1[[#This Row],[FWER]] -> 0.0190639 | BI7: =_xlfn.NUMBERVALUE(MID(Table1[[#This Row],[CI_95perc_Global.Power]],2,FIND(",",Table1[[#This Row],[CI_95perc_Global.Power]])-2)) -> 0.01822 | BJ7: =_xlfn.NUMBERVALUE(MID(Table1[[#This Row],[CI_95perc_Global.Power]],FIND(",",Table1[[#This Row],[CI_95perc_Global.Power]])+1,LEN(Table1[[#This Row],[CI_95perc_Global.Power]])-FIND(",",Table1[[#This Row],[CI_95perc_Global.Power]])-1)) -> 0.01991 | BK7: =_xlfn.NUMBERVALUE(MID(Table1[[#This Row],[CI_95perc_Conjunctive.Power]],2,FIND(",",Table1[[#This Row],[CI_95perc_Conjunctive.Power]])-2)) -> 0 | BL7: =_xlfn.NUMBERVALUE(MID(Table1[[#This Row],[CI_95perc_Conjunctive.Power]],FIND(",",Table1[[#This Row],[CI_95perc_Conjunctive.Power]])+1,LEN(Table1[[#This Row],[CI_95perc_Conjunctive.Power]])-FIND(",",Table1[[#This Row],[CI_95perc_Conjunctive.Power]])-1)) -> 0 | BM7: =_xlfn.NUMBERVALUE(MID(Table1[[#This Row],[CI_95perc_Disjunctive.Power]],2,FIND(",",Table1[[#This Row],[CI_95perc_Disjunctive.Power]])-2)) -> 0 | BN7: =_xlfn.NUMBERVALUE(MID(Table1[[#This Row],[CI_95perc_Disjunctive.Power]],FIND(",",Table1[[#This Row],[CI_95perc_Disjunctive.Power]])+1,LEN(Table1[[#This Row],[CI_95perc_Disjunctive.Power]])-FIND(",",Table1[[#This Row],[CI_95perc_Disjunctive.Power]])-1)) -> 0 | BO7: =_xlfn.NUMBERVALUE(MID(Table1[[#This Row],[CI_95perc_FWER]],2,FIND(",",Table1[[#This Row],[CI_95perc_FWER]])-2)) -> 0.01822 | BP7: =_xlfn.NUMBERVALUE(MID(Table1[[#This Row],[CI_95perc_FWER]],FIND(",",Table1[[#This Row],[CI_95perc_FWER]])+1,LEN(Table1[[#This Row],[CI_95perc_FWER]])-FIND(",",Table1[[#This Row],[CI_95perc_FWER]])-1)) -> 0.01991 | BQ7: =_xlfn.CONCAT("(",TEXT(Table1[[#This Row],[LCL_Disj.Pow%]],"0.00%"), ", ",TEXT(Table1[[#This Row],[UCL_Disj.Pow%]],"0.00%"),")") -> (0.00%, 0.00%) | BR7: =_xlfn.CONCAT("(",TEXT(Table1[[#This Row],[LCL_Conj.Pow%]],"0.00%"),", ",TEXT(Table1[[#This Row],[UCL_Conj.Pow%]],"0.00%"),")") -> (0.00%, 0.00%) | BS7: =_xlfn.CONCAT("(",TEXT(Table1[[#This Row],[LCL_FWER%]],"0.00%"),", ",TEXT(Table1[[#This Row],[UCL_FWER%]],"0.00%"),")") -> (1.82%, 1.99%)
A8: 6 | B8: Fut=0.25,N=3000,MultWin=F | C8: 745664 | D8: 0.0190221 | E8: 0 | F8: 0 | G8: 0.0190221 | H8: (0.01819,0.01985) | I8: (0,0) | J8: (0,0) | K8: (0.01819,0.01985) | L8: 29305 | M8: 0.00145,0.01525 | N8: 0.95829178 | O8: >>> | P8: CER | Q8: 2000 | R8: 0.025 | S8: NA | T8: NA | U8: UnPooled | V8: CombinationTest | W8: 3 | X8: 2 | Y8: list('EP1' = 'Binary', 'EP2' = 'Binary') | Z8: NA | AA8: NA | AB8: list('EP1' = c(0.4, 0.4, 0.4), 'EP2' = c(0.5, 0.5, 0.5)) | AC8: c(1,1,1) | AD8: matrix(c(1, 0.5, 0.5, 1), nrow = nEps) # c(1) | AE8: c(rep(1/4, 4)) | AF8: rbind(H1=c(0, 1/3, 1/3, 1/3), H2=c(1/3, 0, 1/3, 1/3), H3=c(1/3, 1/3, 0, 1/3), H4=c(1/3, 1/3, 1/3, 0)) | AG8: Partly-Parametric | AH8: c(0.5, 1) | AI8: asOF | AJ8: FALSE | AK8: TRUE | AL8: 1 | AM8: 1 | AN8: pvalue | AO8: threshold | AP8: 0.25 | AQ8: TRUE | AR8: Selection | AS8: 20000 | AT8: 2000 | AU8: 745664 | AV8: TRUE | AW8: FALSE | AX8: TRUE | AY8: TRUE | AZ8: NA | BA8: =INDEX(Inp_CER_Bin_2eps3arms!$AN$2:$AN$176,MATCH(Table1[[#This Row],[ModelID]],Inp_CER_Bin_2eps3arms!$A$2:$A$176,0)) -> 0 | BB8: NA | BC8: Aggressive | BD8: S0 | BE8: =Table1[[#This Row],[Global.Power]] -> 0.0190221 | BF8: =Table1[[#This Row],[Conjunctive.Power]] -> 0 | BG8: =Table1[[#This Row],[Disjunctive.Power]] -> 0 | BH8: =Table1[[#This Row],[FWER]] -> 0.0190221 | BI8: =_xlfn.NUMBERVALUE(MID(Table1[[#This Row],[CI_95perc_Global.Power]],2,FIND(",",Table1[[#This Row],[CI_95perc_Global.Power]])-2)) -> 0.01819 | BJ8: =_xlfn.NUMBERVALUE(MID(Table1[[#This Row],[CI_95perc_Global.Power]],FIND(",",Table1[[#This Row],[CI_95perc_Global.Power]])+1,LEN(Table1[[#This Row],[CI_95perc_Global.Power]])-FIND(",",Table1[[#This Row],[CI_95perc_Global.Power]])-1)) -> 0.01985 | BK8: =_xlfn.NUMBERVALUE(MID(Table1[[#This Row],[CI_95perc_Conjunctive.Power]],2,FIND(",",Table1[[#This Row],[CI_95perc_Conjunctive.Power]])-2)) -> 0 | BL8: =_xlfn.NUMBERVALUE(MID(Table1[[#This Row],[CI_95perc_Conjunctive.Power]],FIND(",",Table1[[#This Row],[CI_95perc_Conjunctive.Power]])+1,LEN(Table1[[#This Row],[CI_95perc_Conjunctive.Power]])-FIND(",",Table1[[#This Row],[CI_95perc_Conjunctive.Power]])-1)) -> 0 | BM8: =_xlfn.NUMBERVALUE(MID(Table1[[#This Row],[CI_95perc_Disjunctive.Power]],2,FIND(",",Table1[[#This Row],[CI_95perc_Disjunctive.Power]])-2)) -> 0 | BN8: =_xlfn.NUMBERVALUE(MID(Table1[[#This Row],[CI_95perc_Disjunctive.Power]],FIND(",",Table1[[#This Row],[CI_95perc_Disjunctive.Power]])+1,LEN(Table1[[#This Row],[CI_95perc_Disjunctive.Power]])-FIND(",",Table1[[#This Row],[CI_95perc_Disjunctive.Power]])-1)) -> 0 | BO8: =_xlfn.NUMBERVALUE(MID(Table1[[#This Row],[CI_95perc_FWER]],2,FIND(",",Table1[[#This Row],[CI_95perc_FWER]])-2)) -> 0.01819 | BP8: =_xlfn.NUMBERVALUE(MID(Table1[[#This Row],[CI_95perc_FWER]],FIND(",",Table1[[#This Row],[CI_95perc_FWER]])+1,LEN(Table1[[#This Row],[CI_95perc_FWER]])-FIND(",",Table1[[#This Row],[CI_95perc_FWER]])-1)) -> 0.01985 | BQ8: =_xlfn.CONCAT("(",TEXT(Table1[[#This Row],[LCL_Disj.Pow%]],"0.00%"), ", ",TEXT(Table1[[#This Row],[UCL_Disj.Pow%]],"0.00%"),")") -> (0.00%, 0.00%) | BR8: =_xlfn.CONCAT("(",TEXT(Table1[[#This Row],[LCL_Conj.Pow%]],"0.00%"),", ",TEXT(Table1[[#This Row],[UCL_Conj.Pow%]],"0.00%"),")") -> (0.00%, 0.00%) | BS8: =_xlfn.CONCAT("(",TEXT(Table1[[#This Row],[LCL_FWER%]],"0.00%"),", ",TEXT(Table1[[#This Row],[UCL_FWER%]],"0.00%"),")") -> (1.82%, 1.99%)
A9: 7 | B9: Best=1,N=600,MultWin=F | C9: 745664 | D9: 0.022085 | E9: 0 | F9: 0 | G9: 0.022085 | H9: (0.02125,0.02292) | I9: (0,0) | J9: (0,0) | K9: (0.02125,0.02292) | L9: 32376 | M9: 0.0016,0.0188 | N9: 1.9200537 | O9: >>> | P9: CER | Q9: 600 | R9: 0.025 | S9: NA | T9: NA | U9: UnPooled | V9: CombinationTest | W9: 3 | X9: 2 | Y9: list('EP1' = 'Binary', 'EP2' = 'Binary') | Z9: NA | AA9: NA | AB9: list('EP1' = c(0.4, 0.4, 0.4), 'EP2' = c(0.5, 0.5, 0.5)) | AC9: c(1,1,1) | AD9: matrix(c(1, 0.5, 0.5, 1), nrow = nEps) # c(1) | AE9: c(rep(1/4, 4)) | AF9: rbind(H1=c(0, 1/3, 1/3, 1/3), H2=c(1/3, 0, 1/3, 1/3), H3=c(1/3, 1/3, 0, 1/3), H4=c(1/3, 1/3, 1/3, 0)) | AG9: Partly-Parametric | AH9: c(0.5, 1) | AI9: asOF | AJ9: FALSE | AK9: TRUE | AL9: 1 | AM9: 1 | AN9: pvalue | AO9: best | AP9: 1 | AQ9: TRUE | AR9: Selection | AS9: 20000 | AT9: 2000 | AU9: 745664 | AV9: TRUE | AW9: FALSE | AX9: TRUE | AY9: TRUE | AZ9: NA | BA9: =INDEX(Inp_CER_Bin_2eps3arms!$AN$2:$AN$176,MATCH(Table1[[#This Row],[ModelID]],Inp_CER_Bin_2eps3arms!$A$2:$A$176,0)) -> 0 | BB9: NA | BC9: Ultra Aggressive | BD9: S0 | BE9: =Table1[[#This Row],[Global.Power]] -> 0.022085 | BF9: =Table1[[#This Row],[Conjunctive.Power]] -> 0 | BG9: =Table1[[#This Row],[Disjunctive.Power]] -> 0 | BH9: =Table1[[#This Row],[FWER]] -> 0.022085 | BI9: =_xlfn.NUMBERVALUE(MID(Table1[[#This Row],[CI_95perc_Global.Power]],2,FIND(",",Table1[[#This Row],[CI_95perc_Global.Power]])-2)) -> 0.02125 | BJ9: =_xlfn.NUMBERVALUE(MID(Table1[[#This Row],[CI_95perc_Global.Power]],FIND(",",Table1[[#This Row],[CI_95perc_Global.Power]])+1,LEN(Table1[[#This Row],[CI_95perc_Global.Power]])-FIND(",",Table1[[#This Row],[CI_95perc_Global.Power]])-1)) -> 0.02292 | BK9: =_xlfn.NUMBERVALUE(MID(Table1[[#This Row],[CI_95perc_Conjunctive.Power]],2,FIND(",",Table1[[#This Row],[CI_95perc_Conjunctive.Power]])-2)) -> 0 | BL9: =_xlfn.NUMBERVALUE(MID(Table1[[#This Row],[CI_95perc_Conjunctive.Power]],FIND(",",Table1[[#This Row],[CI_95perc_Conjunctive.Power]])+1,LEN(Table1[[#This Row],[CI_95perc_Conjunctive.Power]])-FIND(",",Table1[[#This Row],[CI_95perc_Conjunctive.Power]])-1)) -> 0 | BM9: =_xlfn.NUMBERVALUE(MID(Table1[[#This Row],[CI_95perc_Disjunctive.Power]],2,FIND(",",Table1[[#This Row],[CI_95perc_Disjunctive.Power]])-2)) -> 0 | BN9: =_xlfn.NUMBERVALUE(MID(Table1[[#This Row],[CI_95perc_Disjunctive.Power]],FIND(",",Table1[[#This Row],[CI_95perc_Disjunctive.Power]])+1,LEN(Table1[[#This Row],[CI_95perc_Disjunctive.Power]])-FIND(",",Table1[[#This Row],[CI_95perc_Disjunctive.Power]])-1)) -> 0 | BO9: =_xlfn.NUMBERVALUE(MID(Table1[[#This Row],[CI_95perc_FWER]],2,FIND(",",Table1[[#This Row],[CI_95perc_FWER]])-2)) -> 0.02125 | BP9: =_xlfn.NUMBERVALUE(MID(Table1[[#This Row],[CI_95perc_FWER]],FIND(",",Table1[[#This Row],[CI_95perc_FWER]])+1,LEN(Table1[[#This Row],[CI_95perc_FWER]])-FIND(",",Table1[[#This Row],[CI_95perc_FWER]])-1)) -> 0.02292 | BQ9: =_xlfn.CONCAT("(",TEXT(Table1[[#This Row],[LCL_Disj.Pow%]],"0.00%"), ", ",TEXT(Table1[[#This Row],[UCL_Disj.Pow%]],"0.00%"),")") -> (0.00%, 0.00%) | BR9: =_xlfn.CONCAT("(",TEXT(Table1[[#This Row],[LCL_Conj.Pow%]],"0.00%"),", ",TEXT(Table1[[#This Row],[UCL_Conj.Pow%]],"0.00%"),")") -> (0.00%, 0.00%) | BS9: =_xlfn.CONCAT("(",TEXT(Table1[[#This Row],[LCL_FWER%]],"0.00%"),", ",TEXT(Table1[[#This Row],[UCL_FWER%]],"0.00%"),")") -> (2.13%, 2.29%)
